Workbook

Sheet Inputs
A1: AVIATION LEASE CASH FLOW MODEL | Model Inputs & Assumptions
A2: Blue = Hardcoded Input | Black = Formula | Green = Cross-sheet Link | Yellow Background = Key Assumption
B4: SCENARIO & DEAL SELECTOR
B5: Active Deal (1=737, 2=A320) | C5: 1
B6: Scenario (1=Base, 2=Upside, 3=Downside) | C6: 1
B8: AIRCRAFT & DEAL ASSUMPTIONS
B9: Parameter | C9: Boeing 737-800 (Deal 1) | E9: Airbus A320neo (Deal 2)
B10: Aircraft Type | C10: Boeing 737-800 | F10: Airbus A320neo
B11: Manufacturer Serial No. | C11: MSN-28024 | F11: MSN-10458
B12: Year of Manufacture | C12: 2018 | F12: 2020
B13: Purchase Price ($) | C13: 72000000 | F13: 85000000
B14: Lease Rate Factor (monthly) | C14: 0.0078 | F14: 0.0082
B15: Monthly Lease Payment ($) | C15: =C14*C13 -> 561600 | F15: =F14*F13 -> 697000
B16: Lease Term (months) | C16: 120 | F16: 144
B17: Lease Start Date | C17: 2024-01-01 | F17: 2024-04-01
B18: Lessee Name | C18: Regional Air Inc. | F18: EuroFly S.A.
B19: Lessee Credit Rating | C19: BB+ | F19: BBB-
B22: DEBT FINANCING ASSUMPTIONS
B23: Parameter | C23: Deal 1 (737) | E23: Deal 2 (A320)
B24: LTV Ratio | C24: 0.75 | F24: 0.7
B25: Loan Amount ($) | C25: =C13*C24 -> 54000000 | F25: =F13*F24 -> 59500000
B26: Annual Interest Rate | C26: 0.055 | F26: 0.06
B27: Amortization Period (months) | C27: 120 | F27: 144
B28: Balloon Payment (% of orig.) | C28: 0.2 | F28: 0.15
B29: Loan Origination Fee (%) | C29: 0.01 | F29: 0.01
B30: DSCR Covenant Minimum | C30: 1.25 | F30: 1.2
B33: OPERATING COSTS & MAINTENANCE RESERVES (Annual)
B34: Cost Item | C34: Deal 1 (737) | E34: Deal 2 (A320)
B35: Servicer / Asset Mgmt Fee ($) | C35: 180000 | F35: 210000
B36: Insurance (Annual $) | C36: 120000 | F36: 140000
B37: Legal & Administrative ($) | C37: 40000 | F37: 50000
B38: Maintenance Reserve - Engine ($) | C38: 450000 | F38: 520000
B39: Maintenance Reserve - Airframe ($) | C39: 180000 | F39: 200000
B40: Other OpEx ($) | C40: 60000 | F40: 75000
B41: Annual Cost Escalation (%) | C41: 0.025 | F41: 0.025
B44: RESIDUAL VALUE & EXIT ASSUMPTIONS
B45: Parameter | C45: Deal 1 (737) | E45: Deal 2 (A320)
B46: Annual Depreciation Rate (%) | C46: 0.035 | F46: 0.03
B47: Base Residual Value ($) | C47: =C13*(1-C46)^(C16/12) -> 50420324 | F47: =F13*(1-F46)^(F16/12) -> 58976601
B48: Haircut to RV (Base %) | C48: 0.05 | F48: 0.05
...

Sheet Debt Schedule
A1: AVIATION LEASE CASH FLOW MODEL | Debt Amortization Schedule
B3: Loan Amount | D3: Interest Rate (Annual) | F3: Amort. Period (mo) | H3: Balloon % | J3: Origination Fee
B4: =Inputs!C76 -> 54000000 | D4: =Inputs!C77 -> 0.055 | F4: =Inputs!C78 -> 120 | H4: =Inputs!C79 -> 0.2 | J4: =Inputs!C87 -> 0.01
B6: Balloon Amount ($) | C6: =Inputs!C76*Inputs!C79 -> 10800000
B7: Monthly Interest Rate | C7: =Inputs!C77/12 -> 0.0045833333
B8: Monthly P&I Payment ($) | C8: =IFERROR(PMT(C7,Inputs!C78,-(Inputs!C76-C6),-C6,0),0) -> 536541.9
B9: Origination Fee ($) | C9: =Inputs!C76*Inputs!C87 -> 540000
B11: Month | C11: Date | D11: Beg. Balance ($) | E11: Scheduled P&I ($) | F11: Interest ($) | G11: Principal ($) | H11: Balloon ($) | I11: Total Debt Svc ($) | J11: End Balance ($) | K11: LTV %
B12: 0 | C12: =DATE(2024,1,1) -> 45292 | D12: =Inputs!C76 -> 54000000 | E12: 0 | F12: 0 | G12: 0 | H12: 0 | I12: 0 | J12: 0 | K12: 0
B13: 1 | C13: =EDATE($C$12,1) -> 45323 | D13: =IF(1>Inputs!$C$78,0,D12) -> 54000000 | E13: =IF(D13=0,0,MIN($C$8,D13+F13)) -> 536541.9 | F13: =IF(D13=0,0,D13*$C$7) -> 247500 | G13: =IF(D13=0,0,E13-F13) -> 289041.9 | H13: =IF(1=Inputs!$C$78,$C$6,0) -> 0 | I13: =IF(D13=0,0,E13+H13) -> 536541.9 | J13: =IF(D13=0,0,MAX(0,D13-G13-H13)) -> 53710958 | K13: =IF(D13=0,0,I13/Inputs!$C$71*(1-Inputs!$C$80)^(1/12)) -> 0.0074298793
B14: 2 | C14: =EDATE($C$12,2) -> 45352 | D14: =IF(2>Inputs!$C$78,0,J13) -> 53710958 | E14: =IF(D14=0,0,MIN($C$8,D14+F14)) -> 536541.9 | F14: =IF(D14=0,0,D14*$C$7) -> 246175.22 | G14: =IF(D14=0,0,E14-F14) -> 290366.68 | H14: =IF(2=Inputs!$C$78,$C$6,0) -> 0 | I14: =IF(D14=0,0,E14+H14) -> 536541.9 | J14: =IF(D14=0,0,MAX(0,D14-G14-H14)) -> 53420591 | K14: =IF(D14=0,0,I14/Inputs!$C$71*(1-Inputs!$C$80)^(2/12)) -> 0.0074078532
B15: 3 | C15: =EDATE($C$12,3) -> 45383 | D15: =IF(3>Inputs!$C$78,0,J14) -> 53420591 | E15: =IF(D15=0,0,MIN($C$8,D15+F15)) -> 536541.9 | F15: =IF(D15=0,0,D15*$C$7) -> 244844.38 | G15: =IF(D15=0,0,E15-F15) -> 291697.52 | H15: =IF(3=Inputs!$C$78,$C$6,0) -> 0 | I15: =IF(D15=0,0,E15+H15) -> 536541.9 | J15: =IF(D15=0,0,MAX(0,D15-G15-H15)) -> 53128894 | K15: =IF(D15=0,0,I15/Inputs!$C$71*(1-Inputs!$C$80)^(3/12)) -> 0.0073858924
B16: 4 | C16: =EDATE($C$12,4) -> 45413 | D16: =IF(4>Inputs!$C$78,0,J15) -> 53128894 | E16: =IF(D16=0,0,MIN($C$8,D16+F16)) -> 536541.9 | F16: =IF(D16=0,0,D16*$C$7) -> 243507.43 | G16: =IF(D16=0,0,E16-F16) -> 293034.47 | H16: =IF(4=Inputs!$C$78,$C$6,0) -> 0 | I16: =IF(D16=0,0,E16+H16) -> 536541.9 | J16: =IF(D16=0,0,MAX(0,D16-G16-H16)) -> 52835859 | K16: =IF(D16=0,0,I16/Inputs!$C$71*(1-Inputs!$C$80)^(4/12)) -> 0.0073639967
B17: 5 | C17: =EDATE($C$12,5) -> 45444 | D17: =IF(5>Inputs!$C$78,0,J16) -> 52835859 | E17: =IF(D17=0,0,MIN($C$8,D17+F17)) -> 536541.9 | F17: =IF(D17=0,0,D17*$C$7) -> 242164.36 | G17: =IF(D17=0,0,E17-F17) -> 294377.55 | H17: =IF(5=Inputs!$C$78,$C$6,0) -> 0 | I17: =IF(D17=0,0,E17+H17) -> 536541.9 | J17: =IF(D17=0,0,MAX(0,D17-G17-H17)) -> 52541482 | K17: =IF(D17=0,0,I17/Inputs!$C$71*(1-Inputs!$C$80)^(5/12)) -> 0.0073421659
B18: 6 | C18: =EDATE($C$12,6) -> 45474 | D18: =IF(6>Inputs!$C$78,0,J17) -> 52541482 | E18: =IF(D18=0,0,MIN($C$8,D18+F18)) -> 536541.9 | F18: =IF(D18=0,0,D18*$C$7) -> 240815.13 | G18: =IF(D18=0,0,E18-F18) -> 295726.78 | H18: =IF(6=Inputs!$C$78,$C$6,0) -> 0 | I18: =IF(D18=0,0,E18+H18) -> 536541.9 | J18: =IF(D18=0,0,MAX(0,D18-G18-H18)) -> 52245755 | K18: =IF(D18=0,0,I18/Inputs!$C$71*(1-Inputs!$C$80)^(6/12)) -> 0.0073203999
B19: 7 | C19: =EDATE($C$12,7) -> 45505 | D19: =IF(7>Inputs!$C$78,0,J18) -> 52245755 | E19: =IF(D19=0,0,MIN($C$8,D19+F19)) -> 536541.9 | F19: =IF(D19=0,0,D19*$C$7) -> 239459.71 | G19: =IF(D19=0,0,E19-F19) -> 297082.19 | H19: =IF(7=Inputs!$C$78,$C$6,0) -> 0 | I19: =IF(D19=0,0,E19+H19) -> 536541.9 | J19: =IF(D19=0,0,MAX(0,D19-G19-H19)) -> 51948673 | K19: =IF(D19=0,0,I19/Inputs!$C$71*(1-Inputs!$C$80)^(7/12)) -> 0.0072986983
B20: 8 | C20: =EDATE($C$12,8) -> 45536 | D20: =IF(8>Inputs!$C$78,0,J19) -> 51948673 | E20: =IF(D20=0,0,MIN($C$8,D20+F20)) -> 536541.9 | F20: =IF(D20=0,0,D20*$C$7) -> 238098.08 | G20: =IF(D20=0,0,E20-F20) -> 298443.82 | H20: =IF(8=Inputs!$C$78,$C$6,0) -> 0 | I20: =IF(D20=0,0,E20+H20) -> 536541.9 | J20: =IF(D20=0,0,MAX(0,D20-G20-H20)) -> 51650229 | K20: =IF(D20=0,0,I20/Inputs!$C$71*(1-Inputs!$C$80)^(8/12)) -> 0.0072770611
B21: 9 | C21: =EDATE($C$12,9) -> 45566 | D21: =IF(9>Inputs!$C$78,0,J20) -> 51650229 | E21: =IF(D21=0,0,MIN($C$8,D21+F21)) -> 536541.9 | F21: =IF(D21=0,0,D21*$C$7) -> 236730.22 | G21: =IF(D21=0,0,E21-F21) -> 299811.68 | H21: =IF(9=Inputs!$C$78,$C$6,0) -> 0 | I21: =IF(D21=0,0,E21+H21) -> 536541.9 | J21: =IF(D21=0,0,MAX(0,D21-G21-H21)) -> 51350417 | K21: =IF(D21=0,0,I21/Inputs!$C$71*(1-Inputs!$C$80)^(9/12)) -> 0.0072554881
B22: 10 | C22: =EDATE($C$12,10) -> 45597 | D22: =IF(10>Inputs!$C$78,0,J21) -> 51350417 | E22: =IF(D22=0,0,MIN($C$8,D22+F22)) -> 536541.9 | F22: =IF(D22=0,0,D22*$C$7) -> 235356.08 | G22: =IF(D22=0,0,E22-F22) -> 301185.82 | H22: =IF(10=Inputs!$C$78,$C$6,0) -> 0 | I22: =IF(D22=0,0,E22+H22) -> 536541.9 | J22: =IF(D22=0,0,MAX(0,D22-G22-H22)) -> 51049232 | K22: =IF(D22=0,0,I22/Inputs!$C$71*(1-Inputs!$C$80)^(10/12)) -> 0.007233979
B23: 11 | C23: =EDATE($C$12,11) -> 45627 | D23: =IF(11>Inputs!$C$78,0,J22) -> 51049232 | E23: =IF(D23=0,0,MIN($C$8,D23+F23)) -> 536541.9 | F23: =IF(D23=0,0,D23*$C$7) -> 233975.64 | G23: =IF(D23=0,0,E23-F23) -> 302566.26 | H23: =IF(11=Inputs!$C$78,$C$6,0) -> 0 | I23: =IF(D23=0,0,E23+H23) -> 536541.9 | J23: =IF(D23=0,0,MAX(0,D23-G23-H23)) -> 50746665 | K23: =IF(D23=0,0,I23/Inputs!$C$71*(1-Inputs!$C$80)^(11/12)) -> 0.0072125336
B24: 12 | C24: =EDATE($C$12,12) -> 45658 | D24: =IF(12>Inputs!$C$78,0,J23) -> 50746665 | E24: =IF(D24=0,0,MIN($C$8,D24+F24)) -> 536541.9 | F24: =IF(D24=0,0,D24*$C$7) -> 232588.88 | G24: =IF(D24=0,0,E24-F24) -> 303953.02 | H24: =IF(12=Inputs!$C$78,$C$6,0) -> 0 | I24: =IF(D24=0,0,E24+H24) -> 536541.9 | J24: =IF(D24=0,0,MAX(0,D24-G24-H24)) -> 50442712 | K24: =IF(D24=0,0,I24/Inputs!$C$71*(1-Inputs!$C$80)^(12/12)) -> 0.0071911519
B25: 13 | C25: =EDATE($C$12,13) -> 45689 | D25: =IF(13>Inputs!$C$78,0,J24) -> 50442712 | E25: =IF(D25=0,0,MIN($C$8,D25+F25)) -> 536541.9 | F25: =IF(D25=0,0,D25*$C$7) -> 231195.76 | G25: =IF(D25=0,0,E25-F25) -> 305346.14 | H25: =IF(13=Inputs!$C$78,$C$6,0) -> 0 | I25: =IF(D25=0,0,E25+H25) -> 536541.9 | J25: =IF(D25=0,0,MAX(0,D25-G25-H25)) -> 50137366 | K25: =IF(D25=0,0,I25/Inputs!$C$71*(1-Inputs!$C$80)^(13/12)) -> 0.0071698335
B26: 14 | C26: =EDATE($C$12,14) -> 45717 | D26: =IF(14>Inputs!$C$78,0,J25) -> 50137366 | E26: =IF(D26=0,0,MIN($C$8,D26+F26)) -> 536541.9 | F26: =IF(D26=0,0,D26*$C$7) -> 229796.26 | G26: =IF(D26=0,0,E26-F26) -> 306745.64 | H26: =IF(14=Inputs!$C$78,$C$6,0) -> 0 | I26: =IF(D26=0,0,E26+H26) -> 536541.9 | J26: =IF(D26=0,0,MAX(0,D26-G26-H26)) -> 49830621 | K26: =IF(D26=0,0,I26/Inputs!$C$71*(1-Inputs!$C$80)^(14/12)) -> 0.0071485783
B27: 15 | C27: =EDATE($C$12,15) -> 45748 | D27: =IF(15>Inputs!$C$78,0,J26) -> 49830621 | E27: =IF(D27=0,0,MIN($C$8,D27+F27)) -> 536541.9 | F27: =IF(D27=0,0,D27*$C$7) -> 228390.34 | G27: =IF(D27=0,0,E27-F27) -> 308151.56 | H27: =IF(15=Inputs!$C$78,$C$6,0) -> 0 | I27: =IF(D27=0,0,E27+H27) -> 536541.9 | J27: =IF(D27=0,0,MAX(0,D27-G27-H27)) -> 49522469 | K27: =IF(D27=0,0,I27/Inputs!$C$71*(1-Inputs!$C$80)^(15/12)) -> 0.0071273862
B28: 16 | C28: =EDATE($C$12,16) -> 45778 | D28: =IF(16>Inputs!$C$78,0,J27) -> 49522469 | E28: =IF(D28=0,0,MIN($C$8,D28+F28)) -> 536541.9 | F28: =IF(D28=0,0,D28*$C$7) -> 226977.98 | G28: =IF(D28=0,0,E28-F28) -> 309563.92 | H28: =IF(16=Inputs!$C$78,$C$6,0) -> 0 | I28: =IF(D28=0,0,E28+H28) -> 536541.9 | J28: =IF(D28=0,0,MAX(0,D28-G28-H28)) -> 49212905 | K28: =IF(D28=0,0,I28/Inputs!$C$71*(1-Inputs!$C$80)^(16/12)) -> 0.0071062568
B29: 17 | C29: =EDATE($C$12,17) -> 45809 | D29: =IF(17>Inputs!$C$78,0,J28) -> 49212905 | E29: =IF(D29=0,0,MIN($C$8,D29+F29)) -> 536541.9 | F29: =IF(D29=0,0,D29*$C$7) -> 225559.15 | G29: =IF(D29=0,0,E29-F29) -> 310982.75 | H29: =IF(17=Inputs!$C$78,$C$6,0) -> 0 | I29: =IF(D29=0,0,E29+H29) -> 536541.9 | J29: =IF(D29=0,0,MAX(0,D29-G29-H29)) -> 48901922 | K29: =IF(D29=0,0,I29/Inputs!$C$71*(1-Inputs!$C$80)^(17/12)) -> 0.0070851901
B30: 18 | C30: =EDATE($C$12,18) -> 45839 | D30: =IF(18>Inputs!$C$78,0,J29) -> 48901922 | E30: =IF(D30=0,0,MIN($C$8,D30+F30)) -> 536541.9 | F30: =IF(D30=0,0,D30*$C$7) -> 224133.81 | G30: =IF(D30=0,0,E30-F30) -> 312408.09 | H30: =IF(18=Inputs!$C$78,$C$6,0) -> 0 | I30: =IF(D30=0,0,E30+H30) -> 536541.9 | J30: =IF(D30=0,0,MAX(0,D30-G30-H30)) -> 48589514 | K30: =IF(D30=0,0,I30/Inputs!$C$71*(1-Inputs!$C$80)^(18/12)) -> 0.0070641859
B31: 19 | C31: =EDATE($C$12,19) -> 45870 | D31: =IF(19>Inputs!$C$78,0,J30) -> 48589514 | E31: =IF(D31=0,0,MIN($C$8,D31+F31)) -> 536541.9 | F31: =IF(D31=0,0,D31*$C$7) -> 222701.94 | G31: =IF(D31=0,0,E31-F31) -> 313839.96 | H31: =IF(19=Inputs!$C$78,$C$6,0) -> 0 | I31: =IF(D31=0,0,E31+H31) -> 536541.9 | J31: =IF(D31=0,0,MAX(0,D31-G31-H31)) -> 48275674 | K31: =IF(D31=0,0,I31/Inputs!$C$71*(1-Inputs!$C$80)^(19/12)) -> 0.0070432439
B32: 20 | C32: =EDATE($C$12,20) -> 45901 | D32: =IF(20>Inputs!$C$78,0,J31) -> 48275674 | E32: =IF(D32=0,0,MIN($C$8,D32+F32)) -> 536541.9 | F32: =IF(D32=0,0,D32*$C$7) -> 221263.51 | G32: =IF(D32=0,0,E32-F32) -> 315278.39 | H32: =IF(20=Inputs!$C$78,$C$6,0) -> 0 | I32: =IF(D32=0,0,E32+H32) -> 536541.9 | J32: =IF(D32=0,0,MAX(0,D32-G32-H32)) -> 47960396 | K32: =IF(D32=0,0,I32/Inputs!$C$71*(1-Inputs!$C$80)^(20/12)) -> 0.007022364
B33: 21 | C33: =EDATE($C$12,21) -> 45931 | D33: =IF(21>Inputs!$C$78,0,J32) -> 47960396 | E33: =IF(D33=0,0,MIN($C$8,D33+F33)) -> 536541.9 | F33: =IF(D33=0,0,D33*$C$7) -> 219818.48 | G33: =IF(D33=0,0,E33-F33) -> 316723.42 | H33: =IF(21=Inputs!$C$78,$C$6,0) -> 0 | I33: =IF(D33=0,0,E33+H33) -> 536541.9 | J33: =IF(D33=0,0,MAX(0,D33-G33-H33)) -> 47643672 | K33: =IF(D33=0,0,I33/Inputs!$C$71*(1-Inputs!$C$80)^(21/12)) -> 0.007001546
B34: 22 | C34: =EDATE($C$12,22) -> 45962 | D34: =IF(22>Inputs!$C$78,0,J33) -> 47643672 | E34: =IF(D34=0,0,MIN($C$8,D34+F34)) -> 536541.9 | F34: =IF(D34=0,0,D34*$C$7) -> 218366.83 | G34: =IF(D34=0,0,E34-F34) -> 318175.07 | H34: =IF(22=Inputs!$C$78,$C$6,0) -> 0 | I34: =IF(D34=0,0,E34+H34) -> 536541.9 | J34: =IF(D34=0,0,MAX(0,D34-G34-H34)) -> 47325497 | K34: =IF(D34=0,0,I34/Inputs!$C$71*(1-Inputs!$C$80)^(22/12)) -> 0.0069807897
B35: 23 | C35: =EDATE($C$12,23) -> 45992 | D35: =IF(23>Inputs!$C$78,0,J34) -> 47325497 | E35: =IF(D35=0,0,MIN($C$8,D35+F35)) -> 536541.9 | F35: =IF(D35=0,0,D35*$C$7) -> 216908.53 | G35: =IF(D35=0,0,E35-F35) -> 319633.37 | H35: =IF(23=Inputs!$C$78,$C$6,0) -> 0 | I35: =IF(D35=0,0,E35+H35) -> 536541.9 | J35: =IF(D35=0,0,MAX(0,D35-G35-H35)) -> 47005864 | K35: =IF(D35=0,0,I35/Inputs!$C$71*(1-Inputs!$C$80)^(23/12)) -> 0.006960095
B36: 24 | C36: =EDATE($C$12,24) -> 46023 | D36: =IF(24>Inputs!$C$78,0,J35) -> 47005864 | E36: =IF(D36=0,0,MIN($C$8,D36+F36)) -> 536541.9 | F36: =IF(D36=0,0,D36*$C$7) -> 215443.54 | G36: =IF(D36=0,0,E36-F36) -> 321098.36 | H36: =IF(24=Inputs!$C$78,$C$6,0) -> 0 | I36: =IF(D36=0,0,E36+H36) -> 536541.9 | J36: =IF(D36=0,0,MAX(0,D36-G36-H36)) -> 46684766 | K36: =IF(D36=0,0,I36/Inputs!$C$71*(1-Inputs!$C$80)^(24/12)) -> 0.0069394616
B37: 25 | C37: =EDATE($C$12,25) -> 46054 | D37: =IF(25>Inputs!$C$78,0,J36) -> 46684766 | E37: =IF(D37=0,0,MIN($C$8,D37+F37)) -> 536541.9 | F37: =IF(D37=0,0,D37*$C$7) -> 213971.84 | G37: =IF(D37=0,0,E37-F37) -> 322570.06 | H37: =IF(25=Inputs!$C$78,$C$6,0) -> 0 | I37: =IF(D37=0,0,E37+H37) -> 536541.9 | J37: =IF(D37=0,0,MAX(0,D37-G37-H37)) -> 46362196 | K37: =IF(D37=0,0,I37/Inputs!$C$71*(1-Inputs!$C$80)^(25/12)) -> 0.0069188893
B38: 26 | C38: =EDATE($C$12,26) -> 46082 | D38: =IF(26>Inputs!$C$78,0,J37) -> 46362196 | E38: =IF(D38=0,0,MIN($C$8,D38+F38)) -> 536541.9 | F38: =IF(D38=0,0,D38*$C$7) -> 212493.4 | G38: =IF(D38=0,0,E38-F38) -> 324048.5 | H38: =IF(26=Inputs!$C$78,$C$6,0) -> 0 | I38: =IF(D38=0,0,E38+H38) -> 536541.9 | J38: =IF(D38=0,0,MAX(0,D38-G38-H38)) -> 46038147 | K38: =IF(D38=0,0,I38/Inputs!$C$71*(1-Inputs!$C$80)^(26/12)) -> 0.0068983781
B39: 27 | C39: =EDATE($C$12,27) -> 46113 | D39: =IF(27>Inputs!$C$78,0,J38) -> 46038147 | E39: =IF(D39=0,0,MIN($C$8,D39+F39)) -> 536541.9 | F39: =IF(D39=0,0,D39*$C$7) -> 211008.17 | G39: =IF(D39=0,0,E39-F39) -> 325533.73 | H39: =IF(27=Inputs!$C$78,$C$6,0) -> 0 | I39: =IF(D39=0,0,E39+H39) -> 536541.9 | J39: =IF(D39=0,0,MAX(0,D39-G39-H39)) -> 45712613 | K39: =IF(D39=0,0,I39/Inputs!$C$71*(1-Inputs!$C$80)^(27/12)) -> 0.0068779276
B40: 28 | C40: =EDATE($C$12,28) -> 46143 | D40: =IF(28>Inputs!$C$78,0,J39) -> 45712613 | E40: =IF(D40=0,0,MIN($C$8,D40+F40)) -> 536541.9 | F40: =IF(D40=0,0,D40*$C$7) -> 209516.14 | G40: =IF(D40=0,0,E40-F40) -> 327025.76 | H40: =IF(28=Inputs!$C$78,$C$6,0) -> 0 | I40: =IF(D40=0,0,E40+H40) -> 536541.9 | J40: =IF(D40=0,0,MAX(0,D40-G40-H40)) -> 45385588 | K40: =IF(D40=0,0,I40/Inputs!$C$71*(1-Inputs!$C$80)^(28/12)) -> 0.0068575378
B41: 29 | C41: =EDATE($C$12,29) -> 46174 | D41: =IF(29>Inputs!$C$78,0,J40) -> 45385588 | E41: =IF(D41=0,0,MIN($C$8,D41+F41)) -> 536541.9 | F41: =IF(D41=0,0,D41*$C$7) -> 208017.28 | G41: =IF(D41=0,0,E41-F41) -> 328524.62 | H41: =IF(29=Inputs!$C$78,$C$6,0) -> 0 | I41: =IF(D41=0,0,E41+H41) -> 536541.9 | J41: =IF(D41=0,0,MAX(0,D41-G41-H41)) -> 45057063 | K41: =IF(D41=0,0,I41/Inputs!$C$71*(1-Inputs!$C$80)^(29/12)) -> 0.0068372085
B42: 30 | C42: =EDATE($C$12,30) -> 46204 | D42: =IF(30>Inputs!$C$78,0,J41) -> 45057063 | E42: =IF(D42=0,0,MIN($C$8,D42+F42)) -> 536541.9 | F42: =IF(D42=0,0,D42*$C$7) -> 206511.54 | G42: =IF(D42=0,0,E42-F42) -> 330030.36 | H42: =IF(30=Inputs!$C$78,$C$6,0) -> 0 | I42: =IF(D42=0,0,E42+H42) -> 536541.9 | J42: =IF(D42=0,0,MAX(0,D42-G42-H42)) -> 44727033 | K42: =IF(D42=0,0,I42/Inputs!$C$71*(1-Inputs!$C$80)^(30/12)) -> 0.0068169394
B43: 31 | C43: =EDATE($C$12,31) -> 46235 | D43: =IF(31>Inputs!$C$78,0,J42) -> 44727033 | E43: =IF(D43=0,0,MIN($C$8,D43+F43)) -> 536541.9 | F43: =IF(D43=0,0,D43*$C$7) -> 204998.9 | G43: =IF(D43=0,0,E43-F43) -> 331543 | H43: =IF(31=Inputs!$C$78,$C$6,0) -> 0 | I43: =IF(D43=0,0,E43+H43) -> 536541.9 | J43: =IF(D43=0,0,MAX(0,D43-G43-H43)) -> 44395490 | K43: =IF(D43=0,0,I43/Inputs!$C$71*(1-Inputs!$C$80)^(31/12)) -> 0.0067967303
...

Sheet Calculations
A1: AVIATION LEASE CASH FLOW MODEL | Monthly Calculations
B3: Month | C3: Date | D3: Lessee Status | E3: Monthly Lease Rev ($) | F3: Monthly OpEx ($) | G3: Maint. Reserve ($) | H3: NOI ($) | I3: Debt Service ($) | J3: CFADS ($) | K3: DSCR | L3: Cum. CFADS ($)
B4: 1 | C4: =EDATE(DATE(2024,1,1),0) -> 45292 | D4: =IF(1>Inputs!$C$74,"Expired",IF(Inputs!$C$68>0,IF(1<Inputs!$C$68,"Paying",IF(1<Inputs!$C$68+Inputs!$C$85,"Default","Re-Lease")),"Paying")) -> Paying | E4: =IF(D4="Expired",0,IF(D4="Default",0,IF(D4="Re-Lease",Inputs!$C$71*Inputs!$C$86,Inputs!$C$73))) -> 561600 | F4: =(Inputs!$C$82*(1+Inputs!$C$83)^0)/12+IF(1=Inputs!$C$68,Inputs!$C$69/12,0) -> 85833.333 | G4: =IF(D4="Expired",0,(IF(Inputs!$C$5=1,(Inputs!C38+Inputs!C39)/12,(Inputs!F38+Inputs!F39)/12)*(1+Inputs!$C$83)^0)) -> 52500 | H4: =E4-F4-G4 -> 423266.67 | I4: ='Debt Schedule'!I13 -> 536541.9 | J4: =H4-I4 -> -113275.23 | K4: =IFERROR(H4/I4,"-") -> 0.78887905 | L4: =SUM($J$4:J4) -> -113275.23
B5: 2 | C5: =EDATE(DATE(2024,1,1),1) -> 45323 | D5: =IF(2>Inputs!$C$74,"Expired",IF(Inputs!$C$68>0,IF(2<Inputs!$C$68,"Paying",IF(2<Inputs!$C$68+Inputs!$C$85,"Default","Re-Lease")),"Paying")) -> Paying | E5: =IF(D5="Expired",0,IF(D5="Default",0,IF(D5="Re-Lease",Inputs!$C$71*Inputs!$C$86,Inputs!$C$73))) -> 561600 | F5: =(Inputs!$C$82*(1+Inputs!$C$83)^0)/12+IF(2=Inputs!$C$68,Inputs!$C$69/12,0) -> 85833.333 | G5: =IF(D5="Expired",0,(IF(Inputs!$C$5=1,(Inputs!C38+Inputs!C39)/12,(Inputs!F38+Inputs!F39)/12)*(1+Inputs!$C$83)^0)) -> 52500 | H5: =E5-F5-G5 -> 423266.67 | I5: ='Debt Schedule'!I14 -> 536541.9 | J5: =H5-I5 -> -113275.23 | K5: =IFERROR(H5/I5,"-") -> 0.78887905 | L5: =SUM($J$4:J5) -> -226550.47
B6: 3 | C6: =EDATE(DATE(2024,1,1),2) -> 45352 | D6: =IF(3>Inputs!$C$74,"Expired",IF(Inputs!$C$68>0,IF(3<Inputs!$C$68,"Paying",IF(3<Inputs!$C$68+Inputs!$C$85,"Default","Re-Lease")),"Paying")) -> Paying | E6: =IF(D6="Expired",0,IF(D6="Default",0,IF(D6="Re-Lease",Inputs!$C$71*Inputs!$C$86,Inputs!$C$73))) -> 561600 | F6: =(Inputs!$C$82*(1+Inputs!$C$83)^0)/12+IF(3=Inputs!$C$68,Inputs!$C$69/12,0) -> 85833.333 | G6: =IF(D6="Expired",0,(IF(Inputs!$C$5=1,(Inputs!C38+Inputs!C39)/12,(Inputs!F38+Inputs!F39)/12)*(1+Inputs!$C$83)^0)) -> 52500 | H6: =E6-F6-G6 -> 423266.67 | I6: ='Debt Schedule'!I15 -> 536541.9 | J6: =H6-I6 -> -113275.23 | K6: =IFERROR(H6/I6,"-") -> 0.78887905 | L6: =SUM($J$4:J6) -> -339825.7
B7: 4 | C7: =EDATE(DATE(2024,1,1),3) -> 45383 | D7: =IF(4>Inputs!$C$74,"Expired",IF(Inputs!$C$68>0,IF(4<Inputs!$C$68,"Paying",IF(4<Inputs!$C$68+Inputs!$C$85,"Default","Re-Lease")),"Paying")) -> Paying | E7: =IF(D7="Expired",0,IF(D7="Default",0,IF(D7="Re-Lease",Inputs!$C$71*Inputs!$C$86,Inputs!$C$73))) -> 561600 | F7: =(Inputs!$C$82*(1+Inputs!$C$83)^0)/12+IF(4=Inputs!$C$68,Inputs!$C$69/12,0) -> 85833.333 | G7: =IF(D7="Expired",0,(IF(Inputs!$C$5=1,(Inputs!C38+Inputs!C39)/12,(Inputs!F38+Inputs!F39)/12)*(1+Inputs!$C$83)^0)) -> 52500 | H7: =E7-F7-G7 -> 423266.67 | I7: ='Debt Schedule'!I16 -> 536541.9 | J7: =H7-I7 -> -113275.23 | K7: =IFERROR(H7/I7,"-") -> 0.78887905 | L7: =SUM($J$4:J7) -> -453100.94
B8: 5 | C8: =EDATE(DATE(2024,1,1),4) -> 45413 | D8: =IF(5>Inputs!$C$74,"Expired",IF(Inputs!$C$68>0,IF(5<Inputs!$C$68,"Paying",IF(5<Inputs!$C$68+Inputs!$C$85,"Default","Re-Lease")),"Paying")) -> Paying | E8: =IF(D8="Expired",0,IF(D8="Default",0,IF(D8="Re-Lease",Inputs!$C$71*Inputs!$C$86,Inputs!$C$73))) -> 561600 | F8: =(Inputs!$C$82*(1+Inputs!$C$83)^0)/12+IF(5=Inputs!$C$68,Inputs!$C$69/12,0) -> 85833.333 | G8: =IF(D8="Expired",0,(IF(Inputs!$C$5=1,(Inputs!C38+Inputs!C39)/12,(Inputs!F38+Inputs!F39)/12)*(1+Inputs!$C$83)^0)) -> 52500 | H8: =E8-F8-G8 -> 423266.67 | I8: ='Debt Schedule'!I17 -> 536541.9 | J8: =H8-I8 -> -113275.23 | K8: =IFERROR(H8/I8,"-") -> 0.78887905 | L8: =SUM($J$4:J8) -> -566376.17
B9: 6 | C9: =EDATE(DATE(2024,1,1),5) -> 45444 | D9: =IF(6>Inputs!$C$74,"Expired",IF(Inputs!$C$68>0,IF(6<Inputs!$C$68,"Paying",IF(6<Inputs!$C$68+Inputs!$C$85,"Default","Re-Lease")),"Paying")) -> Paying | E9: =IF(D9="Expired",0,IF(D9="Default",0,IF(D9="Re-Lease",Inputs!$C$71*Inputs!$C$86,Inputs!$C$73))) -> 561600 | F9: =(Inputs!$C$82*(1+Inputs!$C$83)^0)/12+IF(6=Inputs!$C$68,Inputs!$C$69/12,0) -> 85833.333 | G9: =IF(D9="Expired",0,(IF(Inputs!$C$5=1,(Inputs!C38+Inputs!C39)/12,(Inputs!F38+Inputs!F39)/12)*(1+Inputs!$C$83)^0)) -> 52500 | H9: =E9-F9-G9 -> 423266.67 | I9: ='Debt Schedule'!I18 -> 536541.9 | J9: =H9-I9 -> -113275.23 | K9: =IFERROR(H9/I9,"-") -> 0.78887905 | L9: =SUM($J$4:J9) -> -679651.41
B10: 7 | C10: =EDATE(DATE(2024,1,1),6) -> 45474 | D10: =IF(7>Inputs!$C$74,"Expired",IF(Inputs!$C$68>0,IF(7<Inputs!$C$68,"Paying",IF(7<Inputs!$C$68+Inputs!$C$85,"Default","Re-Lease")),"Paying")) -> Paying | E10: =IF(D10="Expired",0,IF(D10="Default",0,IF(D10="Re-Lease",Inputs!$C$71*Inputs!$C$86,Inputs!$C$73))) -> 561600 | F10: =(Inputs!$C$82*(1+Inputs!$C$83)^0)/12+IF(7=Inputs!$C$68,Inputs!$C$69/12,0) -> 85833.333 | G10: =IF(D10="Expired",0,(IF(Inputs!$C$5=1,(Inputs!C38+Inputs!C39)/12,(Inputs!F38+Inputs!F39)/12)*(1+Inputs!$C$83)^0)) -> 52500 | H10: =E10-F10-G10 -> 423266.67 | I10: ='Debt Schedule'!I19 -> 536541.9 | J10: =H10-I10 -> -113275.23 | K10: =IFERROR(H10/I10,"-") -> 0.78887905 | L10: =SUM($J$4:J10) -> -792926.64
B11: 8 | C11: =EDATE(DATE(2024,1,1),7) -> 45505 | D11: =IF(8>Inputs!$C$74,"Expired",IF(Inputs!$C$68>0,IF(8<Inputs!$C$68,"Paying",IF(8<Inputs!$C$68+Inputs!$C$85,"Default","Re-Lease")),"Paying")) -> Paying | E11: =IF(D11="Expired",0,IF(D11="Default",0,IF(D11="Re-Lease",Inputs!$C$71*Inputs!$C$86,Inputs!$C$73))) -> 561600 | F11: =(Inputs!$C$82*(1+Inputs!$C$83)^0)/12+IF(8=Inputs!$C$68,Inputs!$C$69/12,0) -> 85833.333 | G11: =IF(D11="Expired",0,(IF(Inputs!$C$5=1,(Inputs!C38+Inputs!C39)/12,(Inputs!F38+Inputs!F39)/12)*(1+Inputs!$C$83)^0)) -> 52500 | H11: =E11-F11-G11 -> 423266.67 | I11: ='Debt Schedule'!I20 -> 536541.9 | J11: =H11-I11 -> -113275.23 | K11: =IFERROR(H11/I11,"-") -> 0.78887905 | L11: =SUM($J$4:J11) -> -906201.87
B12: 9 | C12: =EDATE(DATE(2024,1,1),8) -> 45536 | D12: =IF(9>Inputs!$C$74,"Expired",IF(Inputs!$C$68>0,IF(9<Inputs!$C$68,"Paying",IF(9<Inputs!$C$68+Inputs!$C$85,"Default","Re-Lease")),"Paying")) -> Paying | E12: =IF(D12="Expired",0,IF(D12="Default",0,IF(D12="Re-Lease",Inputs!$C$71*Inputs!$C$86,Inputs!$C$73))) -> 561600 | F12: =(Inputs!$C$82*(1+Inputs!$C$83)^0)/12+IF(9=Inputs!$C$68,Inputs!$C$69/12,0) -> 85833.333 | G12: =IF(D12="Expired",0,(IF(Inputs!$C$5=1,(Inputs!C38+Inputs!C39)/12,(Inputs!F38+Inputs!F39)/12)*(1+Inputs!$C$83)^0)) -> 52500 | H12: =E12-F12-G12 -> 423266.67 | I12: ='Debt Schedule'!I21 -> 536541.9 | J12: =H12-I12 -> -113275.23 | K12: =IFERROR(H12/I12,"-") -> 0.78887905 | L12: =SUM($J$4:J12) -> -1019477.1
B13: 10 | C13: =EDATE(DATE(2024,1,1),9) -> 45566 | D13: =IF(10>Inputs!$C$74,"Expired",IF(Inputs!$C$68>0,IF(10<Inputs!$C$68,"Paying",IF(10<Inputs!$C$68+Inputs!$C$85,"Default","Re-Lease")),"Paying")) -> Paying | E13: =IF(D13="Expired",0,IF(D13="Default",0,IF(D13="Re-Lease",Inputs!$C$71*Inputs!$C$86,Inputs!$C$73))) -> 561600 | F13: =(Inputs!$C$82*(1+Inputs!$C$83)^0)/12+IF(10=Inputs!$C$68,Inputs!$C$69/12,0) -> 85833.333 | G13: =IF(D13="Expired",0,(IF(Inputs!$C$5=1,(Inputs!C38+Inputs!C39)/12,(Inputs!F38+Inputs!F39)/12)*(1+Inputs!$C$83)^0)) -> 52500 | H13: =E13-F13-G13 -> 423266.67 | I13: ='Debt Schedule'!I22 -> 536541.9 | J13: =H13-I13 -> -113275.23 | K13: =IFERROR(H13/I13,"-") -> 0.78887905 | L13: =SUM($J$4:J13) -> -1132752.3
B14: 11 | C14: =EDATE(DATE(2024,1,1),10) -> 45597 | D14: =IF(11>Inputs!$C$74,"Expired",IF(Inputs!$C$68>0,IF(11<Inputs!$C$68,"Paying",IF(11<Inputs!$C$68+Inputs!$C$85,"Default","Re-Lease")),"Paying")) -> Paying | E14: =IF(D14="Expired",0,IF(D14="Default",0,IF(D14="Re-Lease",Inputs!$C$71*Inputs!$C$86,Inputs!$C$73))) -> 561600 | F14: =(Inputs!$C$82*(1+Inputs!$C$83)^0)/12+IF(11=Inputs!$C$68,Inputs!$C$69/12,0) -> 85833.333 | G14: =IF(D14="Expired",0,(IF(Inputs!$C$5=1,(Inputs!C38+Inputs!C39)/12,(Inputs!F38+Inputs!F39)/12)*(1+Inputs!$C$83)^0)) -> 52500 | H14: =E14-F14-G14 -> 423266.67 | I14: ='Debt Schedule'!I23 -> 536541.9 | J14: =H14-I14 -> -113275.23 | K14: =IFERROR(H14/I14,"-") -> 0.78887905 | L14: =SUM($J$4:J14) -> -1246027.6
B15: 12 | C15: =EDATE(DATE(2024,1,1),11) -> 45627 | D15: =IF(12>Inputs!$C$74,"Expired",IF(Inputs!$C$68>0,IF(12<Inputs!$C$68,"Paying",IF(12<Inputs!$C$68+Inputs!$C$85,"Default","Re-Lease")),"Paying")) -> Paying | E15: =IF(D15="Expired",0,IF(D15="Default",0,IF(D15="Re-Lease",Inputs!$C$71*Inputs!$C$86,Inputs!$C$73))) -> 561600 | F15: =(Inputs!$C$82*(1+Inputs!$C$83)^0)/12+IF(12=Inputs!$C$68,Inputs!$C$69/12,0) -> 85833.333 | G15: =IF(D15="Expired",0,(IF(Inputs!$C$5=1,(Inputs!C38+Inputs!C39)/12,(Inputs!F38+Inputs!F39)/12)*(1+Inputs!$C$83)^0)) -> 52500 | H15: =E15-F15-G15 -> 423266.67 | I15: ='Debt Schedule'!I24 -> 536541.9 | J15: =H15-I15 -> -113275.23 | K15: =IFERROR(H15/I15,"-") -> 0.78887905 | L15: =SUM($J$4:J15) -> -1359302.8
B16: 13 | C16: =EDATE(DATE(2024,1,1),12) -> 45658 | D16: =IF(13>Inputs!$C$74,"Expired",IF(Inputs!$C$68>0,IF(13<Inputs!$C$68,"Paying",IF(13<Inputs!$C$68+Inputs!$C$85,"Default","Re-Lease")),"Paying")) -> Paying | E16: =IF(D16="Expired",0,IF(D16="Default",0,IF(D16="Re-Lease",Inputs!$C$71*Inputs!$C$86,Inputs!$C$73))) -> 561600 | F16: =(Inputs!$C$82*(1+Inputs!$C$83)^1)/12+IF(13=Inputs!$C$68,Inputs!$C$69/12,0) -> 87979.167 | G16: =IF(D16="Expired",0,(IF(Inputs!$C$5=1,(Inputs!C38+Inputs!C39)/12,(Inputs!F38+Inputs!F39)/12)*(1+Inputs!$C$83)^1)) -> 53812.5 | H16: =E16-F16-G16 -> 419808.33 | I16: ='Debt Schedule'!I25 -> 536541.9 | J16: =H16-I16 -> -116733.57 | K16: =IFERROR(H16/I16,"-") -> 0.78243345 | L16: =SUM($J$4:J16) -> -1476036.4
B17: 14 | C17: =EDATE(DATE(2024,1,1),13) -> 45689 | D17: =IF(14>Inputs!$C$74,"Expired",IF(Inputs!$C$68>0,IF(14<Inputs!$C$68,"Paying",IF(14<Inputs!$C$68+Inputs!$C$85,"Default","Re-Lease")),"Paying")) -> Paying | E17: =IF(D17="Expired",0,IF(D17="Default",0,IF(D17="Re-Lease",Inputs!$C$71*Inputs!$C$86,Inputs!$C$73))) -> 561600 | F17: =(Inputs!$C$82*(1+Inputs!$C$83)^1)/12+IF(14=Inputs!$C$68,Inputs!$C$69/12,0) -> 87979.167 | G17: =IF(D17="Expired",0,(IF(Inputs!$C$5=1,(Inputs!C38+Inputs!C39)/12,(Inputs!F38+Inputs!F39)/12)*(1+Inputs!$C$83)^1)) -> 53812.5 | H17: =E17-F17-G17 -> 419808.33 | I17: ='Debt Schedule'!I26 -> 536541.9 | J17: =H17-I17 -> -116733.57 | K17: =IFERROR(H17/I17,"-") -> 0.78243345 | L17: =SUM($J$4:J17) -> -1592769.9
B18: 15 | C18: =EDATE(DATE(2024,1,1),14) -> 45717 | D18: =IF(15>Inputs!$C$74,"Expired",IF(Inputs!$C$68>0,IF(15<Inputs!$C$68,"Paying",IF(15<Inputs!$C$68+Inputs!$C$85,"Default","Re-Lease")),"Paying")) -> Paying | E18: =IF(D18="Expired",0,IF(D18="Default",0,IF(D18="Re-Lease",Inputs!$C$71*Inputs!$C$86,Inputs!$C$73))) -> 561600 | F18: =(Inputs!$C$82*(1+Inputs!$C$83)^1)/12+IF(15=Inputs!$C$68,Inputs!$C$69/12,0) -> 87979.167 | G18: =IF(D18="Expired",0,(IF(Inputs!$C$5=1,(Inputs!C38+Inputs!C39)/12,(Inputs!F38+Inputs!F39)/12)*(1+Inputs!$C$83)^1)) -> 53812.5 | H18: =E18-F18-G18 -> 419808.33 | I18: ='Debt Schedule'!I27 -> 536541.9 | J18: =H18-I18 -> -116733.57 | K18: =IFERROR(H18/I18,"-") -> 0.78243345 | L18: =SUM($J$4:J18) -> -1709503.5
B19: 16 | C19: =EDATE(DATE(2024,1,1),15) -> 45748 | D19: =IF(16>Inputs!$C$74,"Expired",IF(Inputs!$C$68>0,IF(16<Inputs!$C$68,"Paying",IF(16<Inputs!$C$68+Inputs!$C$85,"Default","Re-Lease")),"Paying")) -> Paying | E19: =IF(D19="Expired",0,IF(D19="Default",0,IF(D19="Re-Lease",Inputs!$C$71*Inputs!$C$86,Inputs!$C$73))) -> 561600 | F19: =(Inputs!$C$82*(1+Inputs!$C$83)^1)/12+IF(16=Inputs!$C$68,Inputs!$C$69/12,0) -> 87979.167 | G19: =IF(D19="Expired",0,(IF(Inputs!$C$5=1,(Inputs!C38+Inputs!C39)/12,(Inputs!F38+Inputs!F39)/12)*(1+Inputs!$C$83)^1)) -> 53812.5 | H19: =E19-F19-G19 -> 419808.33 | I19: ='Debt Schedule'!I28 -> 536541.9 | J19: =H19-I19 -> -116733.57 | K19: =IFERROR(H19/I19,"-") -> 0.78243345 | L19: =SUM($J$4:J19) -> -1826237.1
B20: 17 | C20: =EDATE(DATE(2024,1,1),16) -> 45778 | D20: =IF(17>Inputs!$C$74,"Expired",IF(Inputs!$C$68>0,IF(17<Inputs!$C$68,"Paying",IF(17<Inputs!$C$68+Inputs!$C$85,"Default","Re-Lease")),"Paying")) -> Paying | E20: =IF(D20="Expired",0,IF(D20="Default",0,IF(D20="Re-Lease",Inputs!$C$71*Inputs!$C$86,Inputs!$C$73))) -> 561600 | F20: =(Inputs!$C$82*(1+Inputs!$C$83)^1)/12+IF(17=Inputs!$C$68,Inputs!$C$69/12,0) -> 87979.167 | G20: =IF(D20="Expired",0,(IF(Inputs!$C$5=1,(Inputs!C38+Inputs!C39)/12,(Inputs!F38+Inputs!F39)/12)*(1+Inputs!$C$83)^1)) -> 53812.5 | H20: =E20-F20-G20 -> 419808.33 | I20: ='Debt Schedule'!I29 -> 536541.9 | J20: =H20-I20 -> -116733.57 | K20: =IFERROR(H20/I20,"-") -> 0.78243345 | L20: =SUM($J$4:J20) -> -1942970.7
B21: 18 | C21: =EDATE(DATE(2024,1,1),17) -> 45809 | D21: =IF(18>Inputs!$C$74,"Expired",IF(Inputs!$C$68>0,IF(18<Inputs!$C$68,"Paying",IF(18<Inputs!$C$68+Inputs!$C$85,"Default","Re-Lease")),"Paying")) -> Paying | E21: =IF(D21="Expired",0,IF(D21="Default",0,IF(D21="Re-Lease",Inputs!$C$71*Inputs!$C$86,Inputs!$C$73))) -> 561600 | F21: =(Inputs!$C$82*(1+Inputs!$C$83)^1)/12+IF(18=Inputs!$C$68,Inputs!$C$69/12,0) -> 87979.167 | G21: =IF(D21="Expired",0,(IF(Inputs!$C$5=1,(Inputs!C38+Inputs!C39)/12,(Inputs!F38+Inputs!F39)/12)*(1+Inputs!$C$83)^1)) -> 53812.5 | H21: =E21-F21-G21 -> 419808.33 | I21: ='Debt Schedule'!I30 -> 536541.9 | J21: =H21-I21 -> -116733.57 | K21: =IFERROR(H21/I21,"-") -> 0.78243345 | L21: =SUM($J$4:J21) -> -2059704.2
B22: 19 | C22: =EDATE(DATE(2024,1,1),18) -> 45839 | D22: =IF(19>Inputs!$C$74,"Expired",IF(Inputs!$C$68>0,IF(19<Inputs!$C$68,"Paying",IF(19<Inputs!$C$68+Inputs!$C$85,"Default","Re-Lease")),"Paying")) -> Paying | E22: =IF(D22="Expired",0,IF(D22="Default",0,IF(D22="Re-Lease",Inputs!$C$71*Inputs!$C$86,Inputs!$C$73))) -> 561600 | F22: =(Inputs!$C$82*(1+Inputs!$C$83)^1)/12+IF(19=Inputs!$C$68,Inputs!$C$69/12,0) -> 87979.167 | G22: =IF(D22="Expired",0,(IF(Inputs!$C$5=1,(Inputs!C38+Inputs!C39)/12,(Inputs!F38+Inputs!F39)/12)*(1+Inputs!$C$83)^1)) -> 53812.5 | H22: =E22-F22-G22 -> 419808.33 | I22: ='Debt Schedule'!I31 -> 536541.9 | J22: =H22-I22 -> -116733.57 | K22: =IFERROR(H22/I22,"-") -> 0.78243345 | L22: =SUM($J$4:J22) -> -2176437.8
B23: 20 | C23: =EDATE(DATE(2024,1,1),19) -> 45870 | D23: =IF(20>Inputs!$C$74,"Expired",IF(Inputs!$C$68>0,IF(20<Inputs!$C$68,"Paying",IF(20<Inputs!$C$68+Inputs!$C$85,"Default","Re-Lease")),"Paying")) -> Paying | E23: =IF(D23="Expired",0,IF(D23="Default",0,IF(D23="Re-Lease",Inputs!$C$71*Inputs!$C$86,Inputs!$C$73))) -> 561600 | F23: =(Inputs!$C$82*(1+Inputs!$C$83)^1)/12+IF(20=Inputs!$C$68,Inputs!$C$69/12,0) -> 87979.167 | G23: =IF(D23="Expired",0,(IF(Inputs!$C$5=1,(Inputs!C38+Inputs!C39)/12,(Inputs!F38+Inputs!F39)/12)*(1+Inputs!$C$83)^1)) -> 53812.5 | H23: =E23-F23-G23 -> 419808.33 | I23: ='Debt Schedule'!I32 -> 536541.9 | J23: =H23-I23 -> -116733.57 | K23: =IFERROR(H23/I23,"-") -> 0.78243345 | L23: =SUM($J$4:J23) -> -2293171.4
B24: 21 | C24: =EDATE(DATE(2024,1,1),20) -> 45901 | D24: =IF(21>Inputs!$C$74,"Expired",IF(Inputs!$C$68>0,IF(21<Inputs!$C$68,"Paying",IF(21<Inputs!$C$68+Inputs!$C$85,"Default","Re-Lease")),"Paying")) -> Paying | E24: =IF(D24="Expired",0,IF(D24="Default",0,IF(D24="Re-Lease",Inputs!$C$71*Inputs!$C$86,Inputs!$C$73))) -> 561600 | F24: =(Inputs!$C$82*(1+Inputs!$C$83)^1)/12+IF(21=Inputs!$C$68,Inputs!$C$69/12,0) -> 87979.167 | G24: =IF(D24="Expired",0,(IF(Inputs!$C$5=1,(Inputs!C38+Inputs!C39)/12,(Inputs!F38+Inputs!F39)/12)*(1+Inputs!$C$83)^1)) -> 53812.5 | H24: =E24-F24-G24 -> 419808.33 | I24: ='Debt Schedule'!I33 -> 536541.9 | J24: =H24-I24 -> -116733.57 | K24: =IFERROR(H24/I24,"-") -> 0.78243345 | L24: =SUM($J$4:J24) -> -2409904.9
B25: 22 | C25: =EDATE(DATE(2024,1,1),21) -> 45931 | D25: =IF(22>Inputs!$C$74,"Expired",IF(Inputs!$C$68>0,IF(22<Inputs!$C$68,"Paying",IF(22<Inputs!$C$68+Inputs!$C$85,"Default","Re-Lease")),"Paying")) -> Paying | E25: =IF(D25="Expired",0,IF(D25="Default",0,IF(D25="Re-Lease",Inputs!$C$71*Inputs!$C$86,Inputs!$C$73))) -> 561600 | F25: =(Inputs!$C$82*(1+Inputs!$C$83)^1)/12+IF(22=Inputs!$C$68,Inputs!$C$69/12,0) -> 87979.167 | G25: =IF(D25="Expired",0,(IF(Inputs!$C$5=1,(Inputs!C38+Inputs!C39)/12,(Inputs!F38+Inputs!F39)/12)*(1+Inputs!$C$83)^1)) -> 53812.5 | H25: =E25-F25-G25 -> 419808.33 | I25: ='Debt Schedule'!I34 -> 536541.9 | J25: =H25-I25 -> -116733.57 | K25: =IFERROR(H25/I25,"-") -> 0.78243345 | L25: =SUM($J$4:J25) -> -2526638.5
B26: 23 | C26: =EDATE(DATE(2024,1,1),22) -> 45962 | D26: =IF(23>Inputs!$C$74,"Expired",IF(Inputs!$C$68>0,IF(23<Inputs!$C$68,"Paying",IF(23<Inputs!$C$68+Inputs!$C$85,"Default","Re-Lease")),"Paying")) -> Paying | E26: =IF(D26="Expired",0,IF(D26="Default",0,IF(D26="Re-Lease",Inputs!$C$71*Inputs!$C$86,Inputs!$C$73))) -> 561600 | F26: =(Inputs!$C$82*(1+Inputs!$C$83)^1)/12+IF(23=Inputs!$C$68,Inputs!$C$69/12,0) -> 87979.167 | G26: =IF(D26="Expired",0,(IF(Inputs!$C$5=1,(Inputs!C38+Inputs!C39)/12,(Inputs!F38+Inputs!F39)/12)*(1+Inputs!$C$83)^1)) -> 53812.5 | H26: =E26-F26-G26 -> 419808.33 | I26: ='Debt Schedule'!I35 -> 536541.9 | J26: =H26-I26 -> -116733.57 | K26: =IFERROR(H26/I26,"-") -> 0.78243345 | L26: =SUM($J$4:J26) -> -2643372.1
B27: 24 | C27: =EDATE(DATE(2024,1,1),23) -> 45992 | D27: =IF(24>Inputs!$C$74,"Expired",IF(Inputs!$C$68>0,IF(24<Inputs!$C$68,"Paying",IF(24<Inputs!$C$68+Inputs!$C$85,"Default","Re-Lease")),"Paying")) -> Paying | E27: =IF(D27="Expired",0,IF(D27="Default",0,IF(D27="Re-Lease",Inputs!$C$71*Inputs!$C$86,Inputs!$C$73))) -> 561600 | F27: =(Inputs!$C$82*(1+Inputs!$C$83)^1)/12+IF(24=Inputs!$C$68,Inputs!$C$69/12,0) -> 87979.167 | G27: =IF(D27="Expired",0,(IF(Inputs!$C$5=1,(Inputs!C38+Inputs!C39)/12,(Inputs!F38+Inputs!F39)/12)*(1+Inputs!$C$83)^1)) -> 53812.5 | H27: =E27-F27-G27 -> 419808.33 | I27: ='Debt Schedule'!I36 -> 536541.9 | J27: =H27-I27 -> -116733.57 | K27: =IFERROR(H27/I27,"-") -> 0.78243345 | L27: =SUM($J$4:J27) -> -2760105.6
B28: 25 | C28: =EDATE(DATE(2024,1,1),24) -> 46023 | D28: =IF(25>Inputs!$C$74,"Expired",IF(Inputs!$C$68>0,IF(25<Inputs!$C$68,"Paying",IF(25<Inputs!$C$68+Inputs!$C$85,"Default","Re-Lease")),"Paying")) -> Paying | E28: =IF(D28="Expired",0,IF(D28="Default",0,IF(D28="Re-Lease",Inputs!$C$71*Inputs!$C$86,Inputs!$C$73))) -> 561600 | F28: =(Inputs!$C$82*(1+Inputs!$C$83)^2)/12+IF(25=Inputs!$C$68,Inputs!$C$69/12,0) -> 90178.646 | G28: =IF(D28="Expired",0,(IF(Inputs!$C$5=1,(Inputs!C38+Inputs!C39)/12,(Inputs!F38+Inputs!F39)/12)*(1+Inputs!$C$83)^2)) -> 55157.812 | H28: =E28-F28-G28 -> 416263.54 | I28: ='Debt Schedule'!I37 -> 536541.9 | J28: =H28-I28 -> -120278.36 | K28: =IFERROR(H28/I28,"-") -> 0.77582672 | L28: =SUM($J$4:J28) -> -2880384
B29: 26 | C29: =EDATE(DATE(2024,1,1),25) -> 46054 | D29: =IF(26>Inputs!$C$74,"Expired",IF(Inputs!$C$68>0,IF(26<Inputs!$C$68,"Paying",IF(26<Inputs!$C$68+Inputs!$C$85,"Default","Re-Lease")),"Paying")) -> Paying | E29: =IF(D29="Expired",0,IF(D29="Default",0,IF(D29="Re-Lease",Inputs!$C$71*Inputs!$C$86,Inputs!$C$73))) -> 561600 | F29: =(Inputs!$C$82*(1+Inputs!$C$83)^2)/12+IF(26=Inputs!$C$68,Inputs!$C$69/12,0) -> 90178.646 | G29: =IF(D29="Expired",0,(IF(Inputs!$C$5=1,(Inputs!C38+Inputs!C39)/12,(Inputs!F38+Inputs!F39)/12)*(1+Inputs!$C$83)^2)) -> 55157.812 | H29: =E29-F29-G29 -> 416263.54 | I29: ='Debt Schedule'!I38 -> 536541.9 | J29: =H29-I29 -> -120278.36 | K29: =IFERROR(H29/I29,"-") -> 0.77582672 | L29: =SUM($J$4:J29) -> -3000662.3
B30: 27 | C30: =EDATE(DATE(2024,1,1),26) -> 46082 | D30: =IF(27>Inputs!$C$74,"Expired",IF(Inputs!$C$68>0,IF(27<Inputs!$C$68,"Paying",IF(27<Inputs!$C$68+Inputs!$C$85,"Default","Re-Lease")),"Paying")) -> Paying | E30: =IF(D30="Expired",0,IF(D30="Default",0,IF(D30="Re-Lease",Inputs!$C$71*Inputs!$C$86,Inputs!$C$73))) -> 561600 | F30: =(Inputs!$C$82*(1+Inputs!$C$83)^2)/12+IF(27=Inputs!$C$68,Inputs!$C$69/12,0) -> 90178.646 | G30: =IF(D30="Expired",0,(IF(Inputs!$C$5=1,(Inputs!C38+Inputs!C39)/12,(Inputs!F38+Inputs!F39)/12)*(1+Inputs!$C$83)^2)) -> 55157.812 | H30: =E30-F30-G30 -> 416263.54 | I30: ='Debt Schedule'!I39 -> 536541.9 | J30: =H30-I30 -> -120278.36 | K30: =IFERROR(H30/I30,"-") -> 0.77582672 | L30: =SUM($J$4:J30) -> -3120940.7
B31: 28 | C31: =EDATE(DATE(2024,1,1),27) -> 46113 | D31: =IF(28>Inputs!$C$74,"Expired",IF(Inputs!$C$68>0,IF(28<Inputs!$C$68,"Paying",IF(28<Inputs!$C$68+Inputs!$C$85,"Default","Re-Lease")),"Paying")) -> Paying | E31: =IF(D31="Expired",0,IF(D31="Default",0,IF(D31="Re-Lease",Inputs!$C$71*Inputs!$C$86,Inputs!$C$73))) -> 561600 | F31: =(Inputs!$C$82*(1+Inputs!$C$83)^2)/12+IF(28=Inputs!$C$68,Inputs!$C$69/12,0) -> 90178.646 | G31: =IF(D31="Expired",0,(IF(Inputs!$C$5=1,(Inputs!C38+Inputs!C39)/12,(Inputs!F38+Inputs!F39)/12)*(1+Inputs!$C$83)^2)) -> 55157.812 | H31: =E31-F31-G31 -> 416263.54 | I31: ='Debt Schedule'!I40 -> 536541.9 | J31: =H31-I31 -> -120278.36 | K31: =IFERROR(H31/I31,"-") -> 0.77582672 | L31: =SUM($J$4:J31) -> -3241219.1
B32: 29 | C32: =EDATE(DATE(2024,1,1),28) -> 46143 | D32: =IF(29>Inputs!$C$74,"Expired",IF(Inputs!$C$68>0,IF(29<Inputs!$C$68,"Paying",IF(29<Inputs!$C$68+Inputs!$C$85,"Default","Re-Lease")),"Paying")) -> Paying | E32: =IF(D32="Expired",0,IF(D32="Default",0,IF(D32="Re-Lease",Inputs!$C$71*Inputs!$C$86,Inputs!$C$73))) -> 561600 | F32: =(Inputs!$C$82*(1+Inputs!$C$83)^2)/12+IF(29=Inputs!$C$68,Inputs!$C$69/12,0) -> 90178.646 | G32: =IF(D32="Expired",0,(IF(Inputs!$C$5=1,(Inputs!C38+Inputs!C39)/12,(Inputs!F38+Inputs!F39)/12)*(1+Inputs!$C$83)^2)) -> 55157.812 | H32: =E32-F32-G32 -> 416263.54 | I32: ='Debt Schedule'!I41 -> 536541.9 | J32: =H32-I32 -> -120278.36 | K32: =IFERROR(H32/I32,"-") -> 0.77582672 | L32: =SUM($J$4:J32) -> -3361497.4
B33: 30 | C33: =EDATE(DATE(2024,1,1),29) -> 46174 | D33: =IF(30>Inputs!$C$74,"Expired",IF(Inputs!$C$68>0,IF(30<Inputs!$C$68,"Paying",IF(30<Inputs!$C$68+Inputs!$C$85,"Default","Re-Lease")),"Paying")) -> Paying | E33: =IF(D33="Expired",0,IF(D33="Default",0,IF(D33="Re-Lease",Inputs!$C$71*Inputs!$C$86,Inputs!$C$73))) -> 561600 | F33: =(Inputs!$C$82*(1+Inputs!$C$83)^2)/12+IF(30=Inputs!$C$68,Inputs!$C$69/12,0) -> 90178.646 | G33: =IF(D33="Expired",0,(IF(Inputs!$C$5=1,(Inputs!C38+Inputs!C39)/12,(Inputs!F38+Inputs!F39)/12)*(1+Inputs!$C$83)^2)) -> 55157.812 | H33: =E33-F33-G33 -> 416263.54 | I33: ='Debt Schedule'!I42 -> 536541.9 | J33: =H33-I33 -> -120278.36 | K33: =IFERROR(H33/I33,"-") -> 0.77582672 | L33: =SUM($J$4:J33) -> -3481775.8
B34: 31 | C34: =EDATE(DATE(2024,1,1),30) -> 46204 | D34: =IF(31>Inputs!$C$74,"Expired",IF(Inputs!$C$68>0,IF(31<Inputs!$C$68,"Paying",IF(31<Inputs!$C$68+Inputs!$C$85,"Default","Re-Lease")),"Paying")) -> Paying | E34: =IF(D34="Expired",0,IF(D34="Default",0,IF(D34="Re-Lease",Inputs!$C$71*Inputs!$C$86,Inputs!$C$73))) -> 561600 | F34: =(Inputs!$C$82*(1+Inputs!$C$83)^2)/12+IF(31=Inputs!$C$68,Inputs!$C$69/12,0) -> 90178.646 | G34: =IF(D34="Expired",0,(IF(Inputs!$C$5=1,(Inputs!C38+Inputs!C39)/12,(Inputs!F38+Inputs!F39)/12)*(1+Inputs!$C$83)^2)) -> 55157.812 | H34: =E34-F34-G34 -> 416263.54 | I34: ='Debt Schedule'!I43 -> 536541.9 | J34: =H34-I34 -> -120278.36 | K34: =IFERROR(H34/I34,"-") -> 0.77582672 | L34: =SUM($J$4:J34) -> -3602054.1
B35: 32 | C35: =EDATE(DATE(2024,1,1),31) -> 46235 | D35: =IF(32>Inputs!$C$74,"Expired",IF(Inputs!$C$68>0,IF(32<Inputs!$C$68,"Paying",IF(32<Inputs!$C$68+Inputs!$C$85,"Default","Re-Lease")),"Paying")) -> Paying | E35: =IF(D35="Expired",0,IF(D35="Default",0,IF(D35="Re-Lease",Inputs!$C$71*Inputs!$C$86,Inputs!$C$73))) -> 561600 | F35: =(Inputs!$C$82*(1+Inputs!$C$83)^2)/12+IF(32=Inputs!$C$68,Inputs!$C$69/12,0) -> 90178.646 | G35: =IF(D35="Expired",0,(IF(Inputs!$C$5=1,(Inputs!C38+Inputs!C39)/12,(Inputs!F38+Inputs!F39)/12)*(1+Inputs!$C$83)^2)) -> 55157.812 | H35: =E35-F35-G35 -> 416263.54 | I35: ='Debt Schedule'!I44 -> 536541.9 | J35: =H35-I35 -> -120278.36 | K35: =IFERROR(H35/I35,"-") -> 0.77582672 | L35: =SUM($J$4:J35) -> -3722332.5
B36: 33 | C36: =EDATE(DATE(2024,1,1),32) -> 46266 | D36: =IF(33>Inputs!$C$74,"Expired",IF(Inputs!$C$68>0,IF(33<Inputs!$C$68,"Paying",IF(33<Inputs!$C$68+Inputs!$C$85,"Default","Re-Lease")),"Paying")) -> Paying | E36: =IF(D36="Expired",0,IF(D36="Default",0,IF(D36="Re-Lease",Inputs!$C$71*Inputs!$C$86,Inputs!$C$73))) -> 561600 | F36: =(Inputs!$C$82*(1+Inputs!$C$83)^2)/12+IF(33=Inputs!$C$68,Inputs!$C$69/12,0) -> 90178.646 | G36: =IF(D36="Expired",0,(IF(Inputs!$C$5=1,(Inputs!C38+Inputs!C39)/12,(Inputs!F38+Inputs!F39)/12)*(1+Inputs!$C$83)^2)) -> 55157.812 | H36: =E36-F36-G36 -> 416263.54 | I36: ='Debt Schedule'!I45 -> 536541.9 | J36: =H36-I36 -> -120278.36 | K36: =IFERROR(H36/I36,"-") -> 0.77582672 | L36: =SUM($J$4:J36) -> -3842610.9
B37: 34 | C37: =EDATE(DATE(2024,1,1),33) -> 46296 | D37: =IF(34>Inputs!$C$74,"Expired",IF(Inputs!$C$68>0,IF(34<Inputs!$C$68,"Paying",IF(34<Inputs!$C$68+Inputs!$C$85,"Default","Re-Lease")),"Paying")) -> Paying | E37: =IF(D37="Expired",0,IF(D37="Default",0,IF(D37="Re-Lease",Inputs!$C$71*Inputs!$C$86,Inputs!$C$73))) -> 561600 | F37: =(Inputs!$C$82*(1+Inputs!$C$83)^2)/12+IF(34=Inputs!$C$68,Inputs!$C$69/12,0) -> 90178.646 | G37: =IF(D37="Expired",0,(IF(Inputs!$C$5=1,(Inputs!C38+Inputs!C39)/12,(Inputs!F38+Inputs!F39)/12)*(1+Inputs!$C$83)^2)) -> 55157.812 | H37: =E37-F37-G37 -> 416263.54 | I37: ='Debt Schedule'!I46 -> 536541.9 | J37: =H37-I37 -> -120278.36 | K37: =IFERROR(H37/I37,"-") -> 0.77582672 | L37: =SUM($J$4:J37) -> -3962889.2
B38: 35 | C38: =EDATE(DATE(2024,1,1),34) -> 46327 | D38: =IF(35>Inputs!$C$74,"Expired",IF(Inputs!$C$68>0,IF(35<Inputs!$C$68,"Paying",IF(35<Inputs!$C$68+Inputs!$C$85,"Default","Re-Lease")),"Paying")) -> Paying | E38: =IF(D38="Expired",0,IF(D38="Default",0,IF(D38="Re-Lease",Inputs!$C$71*Inputs!$C$86,Inputs!$C$73))) -> 561600 | F38: =(Inputs!$C$82*(1+Inputs!$C$83)^2)/12+IF(35=Inputs!$C$68,Inputs!$C$69/12,0) -> 90178.646 | G38: =IF(D38="Expired",0,(IF(Inputs!$C$5=1,(Inputs!C38+Inputs!C39)/12,(Inputs!F38+Inputs!F39)/12)*(1+Inputs!$C$83)^2)) -> 55157.812 | H38: =E38-F38-G38 -> 416263.54 | I38: ='Debt Schedule'!I47 -> 536541.9 | J38: =H38-I38 -> -120278.36 | K38: =IFERROR(H38/I38,"-") -> 0.77582672 | L38: =SUM($J$4:J38) -> -4083167.6
B39: 36 | C39: =EDATE(DATE(2024,1,1),35) -> 46357 | D39: =IF(36>Inputs!$C$74,"Expired",IF(Inputs!$C$68>0,IF(36<Inputs!$C$68,"Paying",IF(36<Inputs!$C$68+Inputs!$C$85,"Default","Re-Lease")),"Paying")) -> Paying | E39: =IF(D39="Expired",0,IF(D39="Default",0,IF(D39="Re-Lease",Inputs!$C$71*Inputs!$C$86,Inputs!$C$73))) -> 561600 | F39: =(Inputs!$C$82*(1+Inputs!$C$83)^2)/12+IF(36=Inputs!$C$68,Inputs!$C$69/12,0) -> 90178.646 | G39: =IF(D39="Expired",0,(IF(Inputs!$C$5=1,(Inputs!C38+Inputs!C39)/12,(Inputs!F38+Inputs!F39)/12)*(1+Inputs!$C$83)^2)) -> 55157.812 | H39: =E39-F39-G39 -> 416263.54 | I39: ='Debt Schedule'!I48 -> 536541.9 | J39: =H39-I39 -> -120278.36 | K39: =IFERROR(H39/I39,"-") -> 0.77582672 | L39: =SUM($J$4:J39) -> -4203445.9
B40: 37 | C40: =EDATE(DATE(2024,1,1),36) -> 46388 | D40: =IF(37>Inputs!$C$74,"Expired",IF(Inputs!$C$68>0,IF(37<Inputs!$C$68,"Paying",IF(37<Inputs!$C$68+Inputs!$C$85,"Default","Re-Lease")),"Paying")) -> Paying | E40: =IF(D40="Expired",0,IF(D40="Default",0,IF(D40="Re-Lease",Inputs!$C$71*Inputs!$C$86,Inputs!$C$73))) -> 561600 | F40: =(Inputs!$C$82*(1+Inputs!$C$83)^3)/12+IF(37=Inputs!$C$68,Inputs!$C$69/12,0) -> 92433.112 | G40: =IF(D40="Expired",0,(IF(Inputs!$C$5=1,(Inputs!C38+Inputs!C39)/12,(Inputs!F38+Inputs!F39)/12)*(1+Inputs!$C$83)^3)) -> 56536.758 | H40: =E40-F40-G40 -> 412630.13 | I40: ='Debt Schedule'!I49 -> 536541.9 | J40: =H40-I40 -> -123911.77 | K40: =IFERROR(H40/I40,"-") -> 0.76905481 | L40: =SUM($J$4:J40) -> -4327357.7
B41: 38 | C41: =EDATE(DATE(2024,1,1),37) -> 46419 | D41: =IF(38>Inputs!$C$74,"Expired",IF(Inputs!$C$68>0,IF(38<Inputs!$C$68,"Paying",IF(38<Inputs!$C$68+Inputs!$C$85,"Default","Re-Lease")),"Paying")) -> Paying | E41: =IF(D41="Expired",0,IF(D41="Default",0,IF(D41="Re-Lease",Inputs!$C$71*Inputs!$C$86,Inputs!$C$73))) -> 561600 | F41: =(Inputs!$C$82*(1+Inputs!$C$83)^3)/12+IF(38=Inputs!$C$68,Inputs!$C$69/12,0) -> 92433.112 | G41: =IF(D41="Expired",0,(IF(Inputs!$C$5=1,(Inputs!C38+Inputs!C39)/12,(Inputs!F38+Inputs!F39)/12)*(1+Inputs!$C$83)^3)) -> 56536.758 | H41: =E41-F41-G41 -> 412630.13 | I41: ='Debt Schedule'!I50 -> 536541.9 | J41: =H41-I41 -> -123911.77 | K41: =IFERROR(H41/I41,"-") -> 0.76905481 | L41: =SUM($J$4:J41) -> -4451269.5
...

Sheet Cash Flows
A1: AVIATION LEASE CASH FLOW MODEL | Equity Cash Flows & Returns
B3: INITIAL INVESTMENT (Month 0)
B4: Aircraft Purchase Price | C4: =-Inputs!C71 -> -72000000
B5: Equity Contribution (Purchase Price - Loan) | C5: =-(Inputs!C71-Inputs!C76) -> -18000000
B6: Loan Proceeds | C6: =Inputs!C76 -> 54000000
B7: Origination Fee Paid | C7: =-'Debt Schedule'!C9 -> -540000
B8: NET INITIAL EQUITY OUTFLOW | C8: =C5+C7 -> -18540000
B11: OPERATING PERIOD (Lease Term)
B12: Total Lease Revenue Collected | C12: =SUM(Calculations!E4:E148) -> 134784000
B13: Total Operating Expenses | C13: =-SUM(Calculations!F4:F148) -> -28418839
B14: Total Maintenance Reserves | C14: =-SUM(Calculations!G4:G148) -> -14116261
B15: NET OPERATING INCOME (Total) | C15: =SUM(Calculations!H4:H148) -> 92248900
B16: Total Debt Service Paid | C16: =-SUM(Calculations!I4:I148) -> -1.5037006e+08
B17: CASH FLOW AFTER DEBT SERVICE (CFADS) | C17: =SUM(Calculations!J4:J148) -> -58121156
B20: EXIT / RESIDUAL VALUE
B21: Aircraft Book Value at Exit | C21: =Inputs!C71*(1-Inputs!C80)^(Inputs!C74/12) -> 50420324
B22: RV Haircut (Scenario) | C22: =-C21*Inputs!C81 -> -2521016.2
B23: Net Residual Value Received | C23: =C21+C22 -> 47899308
B24: Remaining Loan Balance at Exit | C24: =IFERROR('Debt Schedule'!I156,0) -> 0
B25: NET EXIT EQUITY PROCEEDS | C25: =C23-C24 -> 47899308
B28: RETURNS SUMMARY
B29: Total Equity Invested | C29: =ABS(C8) -> 18540000
B30: Total Equity Returned (CFADS + Exit) | C30: =C17+C25 -> -10221849
B31: MOIC (Multiple of Invested Capital) | C31: =IFERROR(C30/C29,0) -> -0.55134028
B33: IRR CALCULATION
B34: Monthly IRR (XIRR placeholder) | C34: =IFERROR(IRR(irr_cfs,0.005)*12,"N/A") -> N/A
B35: Annualized Equity IRR | C35: =IFERROR((C30/C29)^(12/Inputs!C74)-1,"N/A") -> N/A
B36: Average Annual DSCR | C36: =IFERROR(AVERAGEIF(Calculations!I4:I148,">"&0,Calculations!H4:H148)/AVERAGEIF(Calculations!I4:I148,">"&0,Calculations!I4:I148),"N/A") -> 0.63123496
B37: Min. Monthly DSCR | C37: =IFERROR(_xludf.minifs(Calculations!K4:K148,Calculations!K4:K148,">"&0),"N/A") -> N/A
B38: DSCR Covenant (Min.) | C38: =Inputs!C84 -> 1.25
B39: Covenant Breach? | C39: =IF(ISNUMBER(C37),IF(C37<C38,"YES - BREACH","No"),"Check") -> Check

Sheet Dashboard
A1: ✈ AVIATION LEASE CASH FLOW MODEL | Executive Dashboard
A2: =IFERROR("Deal: "&IF(Inputs!C5=1,"Boeing 737-800 (MSN-28024)","Airbus A320neo (MSN-10458)")&" | Scenario: "&IF(Inputs!C6=1,"Base",IF(Inputs!C6=2,"Upside","Downside"))&" | As of: "&TEXT(TODAY(),"DD-MMM-YYYY"),"") -> Deal: Boeing 737-800 (MSN-28024) | Scenario: Base | As of: 15-Jun-2026
B4: Equity IRR | C4: MOIC | D4: Avg DSCR | E4: Min DSCR | F4: Total CFADS | G4: RV (Net) | H4: Loan Amount | I4: Covenant
B5: =TEXT('Cash Flows'!C35,"0.0%") -> N/A | C5: =TEXT('Cash Flows'!C31,"0.0x") -> -0.6x | D5: =TEXT('Cash Flows'!C36,"0.00x") -> 0.63x | E5: =TEXT('Cash Flows'!C37,"0.00x") -> N/A | F5: =TEXT('Cash Flows'!C17,"$#,##0") -> -$5,81,21,156 | G5: =TEXT('Cash Flows'!C23,"$#,##0") -> $4,78,99,308 | H5: =TEXT(Inputs!C76,"$#,##0") -> $5,40,00,000 | I5: =IF('Cash Flows'!C39="YES - BREACH","BREACH","OK") -> OK
B8: ▶ Change scenario: Inputs!C6 (1=Base, 2=Upside, 3=Downside) | Change deal: Inputs!C5 (1=737-800, 2=A320neo)
B42: IRR SENSITIVITY: Rate vs. Exit Haircut
B43: Rate \ Haircut | C43: 0% | D43: 5% | E43: 10% | F43: 15% | G43: 20%
B44: 5.5% | C44: 0.1405 | D44: 0.1361 | E44: 0.1316 | F44: 0.1269 | G44: 0.122
B45: 6.0%
B46: 6.5% | C46: 0.1309 | D46: 0.1262 | E46: 0.1213 | F46: 0.1162 | G46: 0.1109 | H46: Cum. CFADS | J46: Component | K46: Amount ($)
B47: 7.0% | C47: 0.1259 | D47: 0.121 | E47: 0.1159 | F47: 0.1105 | G47: 0.1049 | H47: =IFERROR(SUM(Calculations!$L$4:L15),0) -> -8835468.3 | J47: Debt | K47: =Inputs!C76 -> 54000000
B48: 7.5% | C48: 0.1206 | D48: 0.1155 | E48: 0.1101 | F48: 0.1045 | G48: 0.0987 | H48: =IFERROR(SUM(Calculations!$L$4:L27),0) -> -34252320 | J48: Equity | K48: =Inputs!C71-Inputs!C76 -> 18000000
B49: 3 | C49: =IFERROR(1*SUM(Calculations!E28:E39),0) -> 6739200 | D49: =IFERROR(-1*SUM(Calculations!F28:F39),0) -> -1082143.8 | E49: =IFERROR(1*SUM(Calculations!H28:H39),0) -> 4995162.5 | F49: =IFERROR(-1*SUM(Calculations!I28:I39),0) -> -6438502.8 | G49: =IFERROR(1*SUM(Calculations!J28:J39),0) -> -1443340.3 | H49: =IFERROR(SUM(Calculations!$L$4:L39),0) -> -76755300
B50: 4 | C50: =IFERROR(1*SUM(Calculations!E40:E51),0) -> 6739200 | D50: =IFERROR(-1*SUM(Calculations!F40:F51),0) -> -1109197.3 | E50: =IFERROR(1*SUM(Calculations!H40:H51),0) -> 4951561.6 | F50: =IFERROR(-1*SUM(Calculations!I40:I51),0) -> -6438502.8 | G50: =IFERROR(1*SUM(Calculations!J40:J51),0) -> -1486941.2 | H50: =IFERROR(SUM(Calculations!$L$4:L51),0) -> -1.3686177e+08
B51: 5 | C51: =IFERROR(1*SUM(Calculations!E52:E63),0) -> 6739200 | D51: =IFERROR(-1*SUM(Calculations!F52:F63),0) -> -1136927.3 | E51: =IFERROR(1*SUM(Calculations!H52:H63),0) -> 4906870.6 | F51: =IFERROR(-1*SUM(Calculations!I52:I63),0) -> -6438502.8 | G51: =IFERROR(1*SUM(Calculations!J52:J63),0) -> -1531632.2 | H51: =IFERROR(SUM(Calculations!$L$4:L63),0) -> -2.1510202e+08
B52: 6 | C52: =IFERROR(1*SUM(Calculations!E64:E75),0) -> 6739200 | D52: =IFERROR(-1*SUM(Calculations!F64:F75),0) -> -1165350.5 | E52: =IFERROR(1*SUM(Calculations!H64:H75),0) -> 4861062.4 | F52: =IFERROR(-1*SUM(Calculations!I64:I75),0) -> -6438502.8 | G52: =IFERROR(1*SUM(Calculations!J64:J75),0) -> -1577440.4 | H52: =IFERROR(SUM(Calculations!$L$4:L75),0) -> -3.1201962e+08
B53: 7 | C53: =IFERROR(1*SUM(Calculations!E76:E87),0) -> 6739200 | D53: =IFERROR(-1*SUM(Calculations!F76:F87),0) -> -1194484.2 | E53: =IFERROR(1*SUM(Calculations!H76:H87),0) -> 4814108.9 | F53: =IFERROR(-1*SUM(Calculations!I76:I87),0) -> -6438502.8 | G53: =IFERROR(1*SUM(Calculations!J76:J87),0) -> -1624393.9 | H53: =IFERROR(SUM(Calculations!$L$4:L87),0) -> -4.281717e+08
B54: 8 | C54: =IFERROR(1*SUM(Calculations!E88:E99),0) -> 6739200 | D54: =IFERROR(-1*SUM(Calculations!F88:F99),0) -> -1224346.3 | E54: =IFERROR(1*SUM(Calculations!H88:H99),0) -> 4765981.6 | F54: =IFERROR(-1*SUM(Calculations!I88:I99),0) -> -6438502.8 | G54: =IFERROR(1*SUM(Calculations!J88:J99),0) -> -1672521.2 | H54: =IFERROR(SUM(Calculations!$L$4:L99),0) -> -5.6412933e+08
B55: 9 | C55: =IFERROR(1*SUM(Calculations!E100:E111),0) -> 6739200 | D55: =IFERROR(-1*SUM(Calculations!F100:F111),0) -> -1254955 | E55: =IFERROR(1*SUM(Calculations!H100:H111),0) -> 4716651.2 | F55: =IFERROR(-1*SUM(Calculations!I100:I111),0) -> -6438502.8 | G55: =IFERROR(1*SUM(Calculations!J100:J111),0) -> -1721851.6 | H55: =IFERROR(SUM(Calculations!$L$4:L111),0) -> -7.2047787e+08
B56: 10 | C56: =IFERROR(1*SUM(Calculations!E112:E123),0) -> 6739200 | D56: =IFERROR(-1*SUM(Calculations!F112:F123),0) -> -1286328.9 | E56: =IFERROR(1*SUM(Calculations!H112:H123),0) -> 4666087.5 | F56: =IFERROR(-1*SUM(Calculations!I112:I123),0) -> -17238503 | G56: =IFERROR(1*SUM(Calculations!J112:J123),0) -> -12572415 | H56: =IFERROR(SUM(Calculations!$L$4:L123),0) -> -9.0861728e+08
B57: 11 | C57: =IFERROR(1*SUM(Calculations!E124:E135),0) -> 0 | D57: =IFERROR(-1*SUM(Calculations!F124:F135),0) -> -1318487.1 | E57: =IFERROR(1*SUM(Calculations!H124:H135),0) -> -1318487.1 | F57: =IFERROR(-1*SUM(Calculations!I124:I135),0) -> 0 | G57: =IFERROR(1*SUM(Calculations!J124:J135),0) -> -1318487.1 | H57: =IFERROR(SUM(Calculations!$L$4:L135),0) -> -1.2338752e+09
B58: 12 | C58: =IFERROR(1*SUM(Calculations!E136:E147),0) -> 0 | D58: =IFERROR(-1*SUM(Calculations!F136:F147),0) -> -1351449.3 | E58: =IFERROR(1*SUM(Calculations!H136:H147),0) -> -1351449.3 | F58: =IFERROR(-1*SUM(Calculations!I136:I147),0) -> 0 | G58: =IFERROR(1*SUM(Calculations!J136:J147),0) -> -1351449.3 | H58: =IFERROR(SUM(Calculations!$L$4:L147),0) -> -1.5751691e+09

Sheet Python_Reference
A1: PYTHON EQUIVALENT MODEL LOGIC (Reference Only — Not a Working Script)
B2: import pandas as pd
B3: import numpy as np
B4: import numpy_financial as npf
B6: # ── INPUTS ──
B7: purchase_price = 72_000_000 # Boeing 737-800
B8: lrf = 0.0078 # Lease Rate Factor (monthly)
B9: lease_term = 120 # months
B10: ltv = 0.75
B11: loan = purchase_price * ltv
B12: annual_rate = 0.055
B13: monthly_rate = annual_rate / 12
B14: amort_months = 120
... B78: print(f'Min DSCR: {df_cf["dscr"].min():.2f}x')
